Workbook
Name WHO_PM25: Summary!$B$18
Name WHO_PM25_ANNUAL: Summary!$B$19

Sheet Read me
A1: Event cards: deck candidates
A3: What this is
A4: Candidate cards for the event-card game. Each row is one event that can be found on the globe in the monthly history (Aug 2022 - Sep 2026).
A5: Status: Proposed = in the first deck; Maybe = alternate or duplicate; Cut = remove. Change it in the Deck sheet.
A7: Colours
A8: Blue text = measured from the published monthly data (one-off calculation, see below). Do not retype.
A9: Black text = formula or written content.
A10: Yellow cells = still to write: clues, questions, back text, sources.
A11: Cause and misconception columns are first drafts. Every one needs a source before it goes into the game.
A13: How the numbers were measured
A14: Source: public/data/air-history.json and air-month-NN.bin.gz (CAMS global monthly means, 0.4 deg grid).
A15: Box: a rough lon/lat rectangle (W, E, S, N) around the event. The real footprint polygon is drawn later.
... A31: SoGA checks: every figure the report prints for these countries, checked against the stateofglobalair.org data, plus errors found in the report text.

Sheet Deck
A1: # | B1: Status | C1: ID | D1: Name | E1: Type | F1: Rarity | G1: Rarity note | H1: Layer | I1: Month | J1: Region | K1: Box W, E, S, N | L1: Peak (ug/m3) | M1: Peak at (lat, lon) | N1: Area mean (ug/m3) | O1: Usual (ug/m3) | P1: x usual | Q1: PM2.5 peak (ug/m3) | R1: x WHO at peak (not on card) | S1: PM2.5 area mean (ug/m3) | T1: x WHO (card stat): area mean | U1: Area >= 2x usual (k km2) | V1: Same month, other years (area mean) | W1: Main cause (draft) | X1: Common misconception (draft) | Y1: Clue 1: riddle | Z1: Clue 2: region | AA1: Clue 3: country and month | AB1: Question 1 | AC1: Question 2 | AD1: Question 3 | AE1: Back of card | AF1: Sources | AG1: Notes
A2: 1 | B2: Proposed | C2: canada-2023 | D2: Canadian wildfire smoke, June 2023 | E2: Wildfire | F2: Rare | G2: Record Canadian fire season; smoke this dense over the US north-east is unprecedented in the record. | H2: PM2.5 | I2: 2023-06 | J2: Quebec, Ontario and the US north-east | K2: -90, -60, 40, 58 | L2: 138.1 | M2: 51.2, -73.6 | N2: 19.3 | O2: 5.8 | P2: =IFERROR(N2/O2,"") | Q2: 138.1 | R2: =Q2/WHO_PM25 | S2: 19.3 | T2: =S2/WHO_PM25 | U2: 3700 | V2: 2023-06: 19.3 2024-06: 8.9 2025-06: 15.2 2026-06: 7.4 | W2: Hundreds of boreal forest fires in Quebec, many started by lightning in early June after a dry, hot spring; northerly winds carried the smoke south. | X2: That the smoke came from US fires, or that most fires were set by people. | AG2: New York had its worst air on record on 7 June 2023. In the monthly mean, the reach to Europe is weak (1.4x usual), so the footprint should stop at the Atlantic coast. Aug 2023 (NWT) is an alternate for the same season.
A3: 2 | B3: Proposed | C3: south-america-2024 | D3: South American fire smoke, September 2024 | E3: Wildfire | F3: Rare | G3: Record drought year; about 3x the average of the other Septembers in the record. | H3: PM2.5 | I3: 2024-09 | J3: Bolivia, the Pantanal and the southern Amazon | K3: -70, -45, -25, -5 | L3: 526 | M3: -15.6, -62.4 | N3: 45 | O3: 7.1 | P3: =IFERROR(N3/O3,"") | Q3: 526 | R3: =Q3/WHO_PM25 | S3: 45 | T3: =S3/WHO_PM25 | U3: 4769 | V3: 2022-09: 25.2 2023-09: 12.0 2024-09: 45.0 2025-09: 10.1 2026-09: 11.3 | W3: Fires set to clear land and burn pasture spread out of control during a record drought (lowest Amazon river levels on record); Bolivia had its largest burned area on record. | X3: That rainforest fires start naturally. Almost all Amazon fires are set by people. | AG3: Peak cell is in Bolivia (Beni / Santa Cruz). The Pantanal alone is 8.7x usual. August 2024 also elevated; the card could cover Aug-Sep.
A4: 3 | B4: Proposed | C4: indonesia-2026 | D4: Indonesian peat haze, September 2026 | E4: Peat fire | F4: Rare | G4: Highest September in the record, 2.4x the 2023 haze year. Verify against 2015 and 2019 before calling it rare. | H4: PM2.5 | I4: 2026-09 | J4: Kalimantan, Sumatra, Singapore, Malaysia | K4: 95, 120, -6, 4 | L4: 659 | M4: -2.0, 114.0 | N4: 38.2 | O4: 9.9 | P4: =IFERROR(N4/O4,"") | Q4: 659 | R4: =Q4/WHO_PM25 | S4: 38.2 | T4: =S4/WHO_PM25 | U4: 2157 | V4: 2022-09: 10.2 2023-09: 16.1 2024-09: 13.0 2025-09: 10.5 2026-09: 38.2 | W4: Drained peatland burning in Kalimantan and southern Sumatra, mostly fires used to clear land, made worse by El Nino drought. Peat smoulders underground for weeks. | X4: That the haze comes from Singapore or Malaysian industry, or from ordinary forest fires that rain can put out. | AG4: The current Singapore haze. October 2026 joins the history in November; the card should cover Sep-Oct. Peak cell is in Central Kalimantan.
A5: 4 | B5: Proposed | C5: canada-2025 | D5: Manitoba and Saskatchewan fires, June 2025 | E5: Wildfire | F5: Uncommon | G5: Second big Canadian season in three years; 3.4x usual. | H5: PM2.5 | I5: 2025-06 | J5: Manitoba, Saskatchewan, northern US plains | K5: -110, -85, 48, 62 | L5: 69.6 | M5: 55.6, -100.8 | N5: 18.1 | O5: 5.3 | P5: =IFERROR(N5/O5,"") | Q5: 69.6 | R5: =Q5/WHO_PM25 | S5: 18.1 | T5: =S5/WHO_PM25 | U5: 2370 | V5: 2023-06: 16.2 2024-06: 7.3 2025-06: 18.1 2026-06: 6.7 | W5: Boreal forest fires in Manitoba and Saskatchewan after a dry spring; tens of thousands evacuated in late May. | X5: Draft: that 2023 was a one-off. | AG5: Same region as the NWT alternate but a different year, so no footprint clash.
A6: 5 | B6: Proposed | C6: yakutia-2024 | D6: Siberian taiga fires, July 2024 | E6: Wildfire | F6: Uncommon | G6: Yakutia burns big every few years; July 2024 is 6.3x usual. | H6: PM2.5 | I6: 2024-07 | J6: Sakha Republic (Yakutia) and Zabaykalsky, Russia | K6: 110, 150, 58, 72 | L6: 246.5 | M6: 58.8, 117.6 | N6: 18.9 | O6: 3 | P6: =IFERROR(N6/O6,"") | Q6: 246.5 | R6: =Q6/WHO_PM25 | S6: 18.9 | T6: =S6/WHO_PM25 | U6: 2879 | V6: 2023-07: 10.4 2024-07: 18.9 2025-07: 5.9 2026-07: 5.6 | W6: Taiga and peat fires in a hot, dry summer, from lightning and human ignitions; remote and largely left to burn. | X6: Draft: that the Arctic and Siberia are too cold to burn. | AG6: Peak cell is in the south of the box (58.8N 117.6E); the footprint may need to shift south-west.
A7: 6 | B7: Proposed | C7: athens-dust-2024 | D7: Saharan dust over Greece, April 2024 | E7: Dust storm | F7: Uncommon | G7: A strong spring episode; April 2024 is 1.6x the next-highest April (2026). | H7: Dust | I7: 2024-04 | J7: Greece, Crete, Libya coast | K7: 19, 30, 34, 42 | L7: 41.6 | M7: 34.0, 19.6 | N7: 20.2 | O7: 7.1 | P7: =IFERROR(N7/O7,"") | Q7: 32.5 | R7: =Q7/WHO_PM25 | S7: 13.8 | T7: =S7/WHO_PM25 | U7: 841 | V7: 2023-04: 8.6 2024-04: 20.2 2025-04: 8.7 2026-04: 12.4 | W7: Southerly winds ahead of a low-pressure system lifted dust from Libya and carried it across the Mediterranean; Athens turned orange on 23 April. | X7: That the orange sky was wildfire smoke. | AG7: Peak cell is over the sea south of Greece. East-Med dust (Mar 2025) is a near-duplicate; pick one.
A8: 7 | B8: Proposed | C8: iberia-2025 | D8: Spanish and Portuguese fires, August 2025 | E8: Wildfire | F8: Uncommon | G8: Spain's worst fire season in decades (verify the figure); 1.9x usual over a smaller area. | H8: PM2.5 | I8: 2025-08 | J8: Galicia, Castilla y Leon, northern Portugal | K8: -10, 0, 38, 44 | L8: 52.7 | M8: 42.4, -6.8 | N8: 13.6 | O8: 7.1 | P8: =IFERROR(N8/O8,"") | Q8: 52.7 | R8: =Q8/WHO_PM25 | S8: 13.6 | T8: =S8/WHO_PM25 | U8: 239 | V8: 2022-08: 8.9 2023-08: 7.2 2024-08: 8.9 2025-08: 13.6 2026-08: 9.4 | W8: Large fires during an August heatwave in dry, unmanaged rural land with heavy fuel build-up. | X8: Draft: that arson alone explains it. | AG8: Smallest footprint of the proposed cards (239k km2). Could be Rare if the "worst in decades" figure holds.
A9: 8 | B9: Proposed | C9: igp-november | D9: North Indian and Pakistani November smog | E9: Crop burning | F9: Common | G9: Every November; 2024 was the worst of the four years in the record. | H9: PM2.5 | I9: 2024-11 | J9: Punjab (India and Pakistan), Haryana, Delhi, Gangetic plain | K9: 70, 90, 22, 33 | L9: 136.8 | M9: 31.6, 73.2 | N9: 51.4 | O9: 27.2 | P9: =IFERROR(N9/O9,"") | Q9: 136.8 | R9: =Q9/WHO_PM25 | S9: 51.4 | T9: =S9/WHO_PM25 | U9: 906 | V9: 2022-11: 45.6 2023-11: 40.6 2024-11: 51.4 2025-11: 45.3 | W9: Rice-stubble burning in Punjab and Haryana (India) and Pakistani Punjab, trapped by cold, still winter air, on top of year-round local sources (vehicles, industry, dust, household fuel). | X9: That Diwali fireworks cause it. Fireworks add a one- or two-night spike; the month-long haze is mostly crop smoke and trapped local pollution. | AG9: Peak cell (31.6N 73.2E) is in Pakistani Punjab, not Delhi: a good clue. Lahore set records in Nov 2024. The stubble share varies day to day; word answers carefully and cite.
A10: 9 | B10: Proposed | C10: harmattan | D10: Harmattan dust, January 2025 | E10: Dust storm | F10: Common | G10: Every dry season (Nov-Mar). | H10: Dust | I10: 2025-01 | J10: Niger, Nigeria, Chad, West Africa | K10: -17, 15, 5, 15 | L10: 4688 | M10: 11.6, 7.6 | N10: 260.5 | O10: 76.2 | P10: =IFERROR(N10/O10,"") | Q10: 322.5 | R10: =Q10/WHO_PM25 | S10: 47.4 | T10: =S10/WHO_PM25 | U10: 3145 | V10: 2023-01: 91.3 2024-01: 306.5 2025-01: 260.5 2026-01: 225.2 | W10: The dry north-east Harmattan wind carries dust from the Sahara, including the Bodele Depression in Chad, the largest dust source on Earth. | X10: That the haze is fog or city smog. | AG10: Jan 2024 and Feb 2024 are even higher; Jan 2025 chosen to avoid clashing with the Sahel burning card (Dec 2023). Dust peaks are in the thousands of ug/m3 because it is coarse mineral dust.
A11: 10 | B11: Proposed | C11: sahel-burning | D11: West African savanna burning, December 2023 | E11: Savanna burning | F11: Common | G11: Every dry season (Dec-Feb). | H11: PM2.5 | I11: 2023-12 | J11: Nigeria, Cameroon, Central African Republic, Sudan belt | K11: -10, 30, 4, 12 | L11: 309 | M11: 12.0, 6.0 | N11: 45.4 | O11: 16.8 | P11: =IFERROR(N11/O11,"") | Q11: 309 | R11: =Q11/WHO_PM25 | S11: 45.4 | T11: =S11/WHO_PM25 | U11: 2569 | V11: 2022-12: 23.7 2023-12: 45.4 2024-12: 43.4 2025-12: 29.7 | W11: Farmers and herders burn grassland and crop residue in the dry season to clear fields and renew pasture. Africa has most of the world's burned area. | X11: That these are out-of-control wildfires or deforestation. | AG11: Same region as the Harmattan card; months kept apart (Dec 2023 vs Jan 2025).
A12: 11 | B12: Proposed | C12: saharan-dust-caribbean | D12: Saharan dust over the Caribbean, June 2025 | E12: Dust storm | F12: Common | G12: Every summer. | H12: Dust | I12: 2025-06 | J12: Tropical Atlantic, Caribbean, Gulf of Mexico | K12: -85, -55, 10, 25 | L12: 37.2 | M12: 11.6, -55.6 | N12: 19 | O12: 2.2 | P12: =IFERROR(N12/O12,"") | Q12: 36.1 | R12: =Q12/WHO_PM25 | S12: 13.9 | T12: =S12/WHO_PM25 | U12: 5232 | V12: 2023-06: 11.1 2024-06: 15.0 2025-06: 19.0 2026-06: 12.6 | W12: The Saharan Air Layer carries dust about 8,000 km across the Atlantic each summer. | X12: That the haze is local pollution, or that desert dust stays in the desert. | AG12: Peak sits at the east edge of the box: the footprint must extend east across the Atlantic toward Africa.
A13: 12 | B13: Proposed | C13: central-africa-burning | D13: Central African burning season, July 2024 | E13: Savanna burning | F13: Common | G13: Every dry season (Jun-Sep). | H13: PM2.5 | I13: 2024-07 | J13: Angola, DR Congo, Zambia | K13: 12, 35, -15, 0 | L13: 62 | M13: -6.4, 21.6 | N13: 26.1 | O13: 12.9 | P13: =IFERROR(N13/O13,"") | Q13: 62 | R13: =Q13/WHO_PM25 | S13: 26.1 | T13: =S13/WHO_PM25 | U13: 2022 | V13: 2023-07: 19.7 2024-07: 26.1 2025-07: 22.4 2026-07: 28.6 | W13: Seasonal burning of savanna, cropland and woodland mosaic in the southern dry season, the densest fire activity on Earth. | X13: That the Congo rainforest is burning. | AG13: July 2026 is slightly higher (28.6); either works.
... A16: 15 | B16: Proposed | C16: gobi-dust | D16: Gobi spring dust, April 2025 | E16: Dust storm | F16: Common | G16: Every spring. | H16: Dust | I16: 2025-04 | J16: Inner Mongolia, northern China, Korea | K16: 105, 130, 33, 45 | L16: 2013 | M16: 34.8, 110.8 | N16: 142.3 | O16: 33.7 | P16: =IFERROR(N16/O16,"") | Q16: 115.7 | R16: =Q16/WHO_PM25 | S16: 28.3 | T16: =S16/WHO_PM25 | U16: 2870 | V16: 2023-04: 56.3 2024-04: 71.7 2025-04: 142.3 2026-04: 140.6 | W16: Spring cold fronts lift dust from the Gobi and northern Chinese deserts; it reaches Beijing, Korea and Japan ("yellow dust"). | X16: That it is industrial smog. | AG16: Peak cell (34.8N 110.8E) is on the Loess Plateau; check this is dust transport, not a model artefact.
A17: 16 | B17: Maybe | C17: canada-nwt-2023 | D17: Northwest Territories fires, August 2023 | E17: Wildfire | F17: Uncommon | G17: Same record season as the June card. | H17: PM2.5 | I17: 2023-08 | J17: Northwest Territories, British Columbia, Alberta | K17: -135, -100, 50, 68 | L17: 258.2 | M17: 60.4, -116.8 | N17: 23.2 | O17: 4.4 | P17: =IFERROR(N17/O17,"") | Q17: 258.2 | R17: =Q17/WHO_PM25 | S17: 23.2 | T17: =S17/WHO_PM25 | U17: 3449 | V17: 2022-08: 5.2 2023-08: 23.2 2024-08: 15.7 2025-08: 11.9 2026-08: 9.3 | W17: Boreal fires that forced the evacuation of Yellowknife. | AG17: Strong (5.3x) but duplicates the 2023 season. Keep only if we want two cards from one year.
A18: 17 | B18: Maybe | C18: indonesia-2023 | D18: Indonesian peat haze, October 2023 | E18: Peat fire | F18: Uncommon | G18: El Nino year haze. | H18: PM2.5 | I18: 2023-10 | J18: Kalimantan, Sumatra | K18: 95, 120, -6, 4 | L18: 107.8 | M18: -2.4, 114.0 | N18: 16 | O18: 9.9 | P18: =IFERROR(N18/O18,"") | Q18: 107.8 | R18: =Q18/WHO_PM25 | S18: 16 | T18: =S18/WHO_PM25 | U18: 826 | V18: 2022-10: 7.9 2023-10: 16.0 2024-10: 11.3 2025-10: 9.9 | W18: Same cause as the 2026 card. | AG18: Duplicates the 2026 card at a third of its strength.
A19: 18 | B19: Maybe | C19: gulf-shamal | D19: Gulf shamal dust, June 2024 | E19: Dust storm | F19: Common | G19: Every summer. | H19: Dust | I19: 2024-06 | J19: Iraq, Kuwait, eastern Saudi Arabia | K19: 44, 58, 22, 32 | L19: 1765 | M19: 29.6, 48.0 | N19: 280.9 | O19: 184.3 | P19: =IFERROR(N19/O19,"") | Q19: 137 | R19: =Q19/WHO_PM25 | S19: 28 | T19: =S19/WHO_PM25 | U19: 317 | V19: 2023-06: 175.4 2024-06: 280.9 2025-06: 257.1 2026-06: 202.9 | W19: The summer shamal wind lifts dust from Iraq and Syria. | AG19: Only 1.5x usual: the region is always dusty, so the event barely stands out on the globe.
A20: 19 | B20: Maybe | C20: east-med-dust | D20: Eastern Mediterranean dust, March 2025 | E20: Dust storm | F20: Common | G20: Most springs. | H20: Dust | I20: 2025-03 | J20: Libya, Egypt, eastern Mediterranean | K20: 19, 36, 30, 42 | L20: 1217 | M20: 30.4, 21.2 | N20: 62.1 | O20: 31.2 | P20: =IFERROR(N20/O20,"") | Q20: 81.8 | R20: =Q20/WHO_PM25 | S20: 15.3 | T20: =S20/WHO_PM25 | U20: 1559 | V20: 2023-03: 25.7 2024-03: 57.5 2025-03: 62.1 2026-03: 49.6 | W20: Spring Saharan dust outbreaks. | AG20: Near-duplicate of the Greece card.

Sheet Summary
A1: Proposed cards by rarity
A2: Rarity | B2: Proposed | C2: Target | D2: Maybe
A3: Common | B3: =COUNTIFS(Deck!$F$2:$F$200,A3,Deck!$B$2:$B$200,"Proposed") | C3: 10 | D3: =COUNTIFS(Deck!$F$2:$F$200,A3,Deck!$B$2:$B$200,"Maybe")
A4: Uncommon | B4: =COUNTIFS(Deck!$F$2:$F$200,A4,Deck!$B$2:$B$200,"Proposed") | C4: 6 | D4: =COUNTIFS(Deck!$F$2:$F$200,A4,Deck!$B$2:$B$200,"Maybe")
A5: Rare | B5: =COUNTIFS(Deck!$F$2:$F$200,A5,Deck!$B$2:$B$200,"Proposed") | C5: 4 | D5: =COUNTIFS(Deck!$F$2:$F$200,A5,Deck!$B$2:$B$200,"Maybe")
A6: Total | B6: =SUM(B3:B5) | C6: =SUM(C3:C5) | D6: =SUM(D3:D5)
A8: Proposed cards by type
A9: Wildfire | B9: =COUNTIFS(Deck!$E$2:$E$200,A9,Deck!$B$2:$B$200,"Proposed")
A10: Peat fire | B10: =COUNTIFS(Deck!$E$2:$E$200,A10,Deck!$B$2:$B$200,"Proposed")
A11: Crop burning | B11: =COUNTIFS(Deck!$E$2:$E$200,A11,Deck!$B$2:$B$200,"Proposed")
A12: Savanna burning | B12: =COUNTIFS(Deck!$E$2:$E$200,A12,Deck!$B$2:$B$200,"Proposed")
A13: Dust storm | B13: =COUNTIFS(Deck!$E$2:$E$200,A13,Deck!$B$2:$B$200,"Proposed")
A15: Targets are the 10 / 6 / 4 split agreed in discussion.
A17: Constants
A18: WHO 2021 PM2.5 24-hour guideline (ug/m3) | B18: 15 | C18: Source: WHO global air quality guidelines, 2021, Table 0.1 (24-hour PM2.5 = 15 ug/m3)
A19: WHO 2021 PM2.5 annual guideline (ug/m3) | B19: 5 | C19: Source: WHO global air quality guidelines, 2021, Table 0.1 (annual PM2.5 = 5 ug/m3). Used only on the SoGA context sheet.

Sheet Types
A1: Type | B1: What it means | C1: Layer
A2: Wildfire | B2: Forest or bush fires, often lightning-started or escaped land-clearing fires. | C2: PM2.5
A3: Peat fire | B3: Drained peatland burning underground for weeks; dense, long-lasting haze. | C3: PM2.5
A4: Crop burning | B4: Farmers burning crop residue or clearing fields; seasonal and human-set. | C4: PM2.5
A5: Savanna burning | B5: Seasonal grassland and woodland burning, mostly managed fires. | C5: PM2.5
A6: Dust storm | B6: Wind lifting desert dust, sometimes carried across oceans. | C6: Dust
A8: Accident, transit, fireworks and urban/industry types were considered but no event of that kind shows in the monthly data. See Not visible.

Sheet Not visible
A1: Event | B1: Layer | C1: Month | D1: x usual | E1: Area >= 2x usual (k km2) | F1: Why it is out
A2: Los Angeles fires | B2: PM2.5 | C2: 2025-01 | D2: 1.2 | E2: 3 | F2: A few days over a small area; vanishes in the monthly mean.
A3: Evros fire, Greece | B3: PM2.5 | C3: 2023-08 | D3: 1 | E3: 0 | F3: Not visible at 45 km monthly.
A4: Maui fire | B4: PM2.5 | C4: 2023-08 | F4: Island-scale, smaller than one grid cell. Not measured.
A5: East Palestine train derailment | B5: PM2.5 | C5: 2023-02 | F5: Local chemical release; not in these fields. Not measured. (Accident type.)
A6: Diwali night | B6: PM2.5 | C6: Nov | F6: One or two nights; diluted into the North India November card, where it becomes the misconception question.
A7: Lahore smog, Nov 2024 | B7: PM2.5 | C7: 2024-11 | F7: Same place and month as the North India November card; merged into it.
A8: Red Sea shipping NO2 | B8: NO2 | C8: 2024-06 | D8: 1.3 | E8: 124 | F8: Ship plumes are too faint at the surface in monthly means. (Transit type.)
A9: Highveld coal NO2, South Africa | B9: NO2 | C9: 2024-07 | D9: 1.2 | E9: 23 | F9: A constant hotspot, not an event: "x usual" stays near 1.
A10: North China winter NO2 and PM2.5 | B10: NO2 | C10: 2024-01 | D10: 1.3 | E10: 0 | F10: Constant winter pollution, not an event.
A11: Ulaanbaatar winter smog | B11: PM2.5 | C11: 2024-01 | D11: 0.9 | E11: 3 | F11: City-scale; too small for the grid.
A12: Canadian smoke over Europe | B12: PM2.5 | C12: 2023-06 | D12: 1.4 | E12: 106 | F12: Real but faint in the monthly mean; part of the Canada 2023 card at most.
A13: Northern Australia, Dec 2023 | B13: PM2.5 | C13: 2023-12 | D13: 1.3 | E13: 232 | F13: Weak and not a named event.

Sheet SoGA context
A1: # | B1: Card ID | C1: Country | D1: PM2.5 2013 (ug/m3) | E1: PM2.5 2015 | F1: PM2.5 2019 | G1: PM2.5 2022 | H1: PM2.5 2023 | I1: PM2.5 2023, 95% UI | J1: Change 2013 to 2023 | K1: x WHO annual (2023) | L1: Cooking with solid fuels, 2023 (% of people) | M1: Ozone 2020 (ppb) | N1: Deaths linked to air pollution, 2023 | O1: Deaths, 95% UI | P1: of which outdoor PM2.5 | Q1: of which household smoke | R1: Death rate, age-standardised (per 100,000) | S1: Also printed in the report | T1: Card-back draft (one per card)
A2: 1 | B2: canada-2023 | C2: Canada | D2: 7.14 | E2: 7.39 | F2: 6.45 | G2: 6.39 | H2: 6.55 | I2: 6.34–6.77 | J2: =IFERROR(H2/D2-1,"") | K2: =H2/WHO_PM25_ANNUAL | L2: 0.16 | M2: 37.2 | N2: 7060 | O2: 3,740–12,200 | P2: 6270 | Q2: 29.3 | R2: 8.23 | T2: Averaged over all of Canada and all of 2023, PM2.5 was 6.6 µg/m³, lower than in 2021 (7.8). A month of record smoke almost disappears in a yearly national average.
A3: 1 | B3: canada-2023 | C3: United States of America | D3: 8.43 | E3: 8.05 | F3: 7.27 | G3: 7.43 | H3: 6.97 | I3: 6.9–7.04 | J3: =IFERROR(H3/D3-1,"") | K3: =H3/WHO_PM25_ANNUAL | L3: 0.2 | M3: 43.1 | N3: 82500 | O3: 44,300–135,100 | P3: 69700 | Q3: 384 | R3: 13
A4: 2 | B4: south-america-2024 | C4: Bolivia (Plurinational State of) | D4: 25.2 | E4: 27.2 | F4: 28.9 | G4: 30.6 | H4: 28.1 | I4: 27.5–28.8 | J4: =IFERROR(H4/D4-1,"") | K4: =H4/WHO_PM25_ANNUAL | L4: 10.8 | M4: 41.1 | N4: 6540 | O4: 5,080–8,110 | P4: 4830 | Q4: 1620 | R4: 75.6 | T4: In 2023, air pollution was linked to about 6,500 deaths in Bolivia. Its yearly PM2.5 (28 µg/m³) is about double Brazil's (13).
A5: 2 | B5: south-america-2024 | C5: Brazil | D5: 13.2 | E5: 14.1 | F5: 13.8 | G5: 14.9 | H5: 13.4 | I5: 13.1–13.6 | J5: =IFERROR(H5/D5-1,"") | K5: =H5/WHO_PM25_ANNUAL | L5: 4.4 | M5: 40.5 | N5: 87400 | O5: 60,100–118,700 | P5: 78000 | Q5: 5080 | R5: 34.6
A6: 2 | B6: south-america-2024 | C6: Paraguay | D6: 12.2 | E6: 15 | F6: 16.4 | G6: 14.4 | H6: 15.3 | I6: 14.9–15.7 | J6: =IFERROR(H6/D6-1,"") | K6: =H6/WHO_PM25_ANNUAL | L6: 23.8 | M6: 41.7 | N6: 3790 | O6: 2,790–4,960 | P6: 2570 | Q6: 1130 | R6: 77.7
A7: 3 | B7: indonesia-2026 | C7: Indonesia | D7: 19.4 | E7: 25.6 | F7: 24 | G7: 19.8 | H7: 20.8 | I7: 20.2–21.5 | J7: =IFERROR(H7/D7-1,"") | K7: =H7/WHO_PM25_ANNUAL | L7: 18 | M7: 38 | N7: 192100 | O7: 146,200–242,500 | P7: 147100 | Q7: 42700 | R7: 82.2 | S7: p.4, 24: >100,000 deaths | T7: In 2023, air pollution was linked to about 192,000 deaths in Indonesia. Haze years show even in yearly averages: Singapore's PM2.5 reached 26.8 µg/m³ in 2015 and 18.9 in 2019, against about 15 in other recent years.
A8: 3 | B8: indonesia-2026 | C8: Singapore | D8: 25.5 | E8: 26.8 | F8: 18.9 | G8: 15.1 | H8: 15.1 | I8: 13–17.3 | J8: =IFERROR(H8/D8-1,"") | K8: =H8/WHO_PM25_ANNUAL | L8: 0.56 | M8: 45.6 | N8: 2300 | O8: 1,260–3,400 | P8: 2240 | Q8: 14.8 | R8: 25.2
A9: 3 | B9: indonesia-2026 | C9: Malaysia | D9: 19.7 | E9: 25.2 | F9: 20.9 | G9: 15.3 | H9: 15.9 | I9: 15.4–16.3 | J9: =IFERROR(H9/D9-1,"") | K9: =H9/WHO_PM25_ANNUAL | L9: 1.04 | M9: 39.1 | N9: 16300 | O9: 12,000–21,000 | P9: 15900 | Q9: 57.3 | R9: 58
A10: 4 | B10: canada-2025 | C10: Canada | D10: 7.14 | E10: 7.39 | F10: 6.45 | G10: 6.39 | H10: 6.55 | I10: 6.34–6.77 | J10: =IFERROR(H10/D10-1,"") | K10: =H10/WHO_PM25_ANNUAL | L10: 0.16 | M10: 37.2 | N10: 7060 | O10: 3,740–12,200 | P10: 6270 | Q10: 29.3 | R10: 8.23 | T10: In 2023, Canada's death rate linked to air pollution was 8 per 100,000 people, against 92 worldwide.
A11: 5 | B11: yakutia-2024 | C11: Russian Federation | D11: 14.2 | E11: 13.1 | F11: 12.6 | G11: 11.8 | H11: 11.6 | I11: 11.4–11.7 | J11: =IFERROR(H11/D11-1,"") | K11: =H11/WHO_PM25_ANNUAL | L11: 2.15 | M11: 35.7 | N11: 91700 | O11: 59,500–128,700 | P11: 89700 | Q11: 1060 | R11: 38 | T11: In 2023, air pollution was linked to about 92,000 deaths in Russia, almost all of them from outdoor PM2.5.
A12: 6 | B12: athens-dust-2024 | C12: Greece | D12: 15.1 | E12: 15.5 | F12: 15.5 | G12: 16.3 | H12: 14.1 | I12: 13.6–14.7 | J12: =IFERROR(H12/D12-1,"") | K12: =H12/WHO_PM25_ANNUAL | L12: 0.4 | M12: 46.2 | N12: 9340 | O12: 6,180–13,500 | P12: 8920 | Q12: 20.6 | R12: 29.8 | T12: Greece's yearly PM2.5 was 14.1 µg/m³ in 2023, nearly three times the WHO annual guideline of 5. Saharan dust is part of that average.
A13: 6 | B13: athens-dust-2024 | C13: Libya | D13: 26 | E13: 19.9 | F13: 20 | G13: 23.2 | H13: 20 | I13: 19.6–20.4 | J13: =IFERROR(H13/D13-1,"") | K13: =H13/WHO_PM25_ANNUAL | L13: 0.16 | M13: 54.2 | N13: 3270 | O13: 2,330–4,060 | P13: 3190 | Q13: 6.41 | R13: 69.5
A14: 7 | B14: iberia-2025 | C14: Spain | D14: 10.3 | E14: 11.8 | F14: 10.4 | G14: 11.9 | H14: 10.1 | I14: 9.83–10.3 | J14: =IFERROR(H14/D14-1,"") | K14: =H14/WHO_PM25_ANNUAL | L14: 0.77 | M14: 48.1 | N14: 21500 | O14: 12,700–34,800 | P14: 19000 | Q14: 123 | R14: 16.2 | T14: In 2023, air pollution was linked to about 21,500 deaths in Spain and 4,700 in Portugal.
A15: 7 | B15: iberia-2025 | C15: Portugal | D15: 9.11 | E15: 10.1 | F15: 8.28 | G15: 9.24 | H15: 8.77 | I15: 8.39–9.11 | J15: =IFERROR(H15/D15-1,"") | K15: =H15/WHO_PM25_ANNUAL | L15: 1 | M15: 39.8 | N15: 4710 | O15: 2,550–7,860 | P15: 4380 | Q15: 29 | R15: 14.6
A16: 8 | B16: igp-november | C16: India | D16: 52.3 | E16: 51.4 | F16: 53.6 | G16: 50.7 | H16: 54.1 | I16: 53.7–54.4 | J16: =IFERROR(H16/D16-1,"") | K16: =H16/WHO_PM25_ANNUAL | L16: 41.8 | M16: 67.2 | N16: 2006000 | O16: 1,667,000–2,359,000 | P16: 969700 | Q16: 937800 | R16: 186 | S16: p.4, 24: >2 million deaths | T16: In 2023, air pollution was linked to about 2 million deaths in India and 248,000 in Pakistan. In India, household cooking smoke accounted for 938,000 of them, almost as many as outdoor PM2.5 (970,000).
A17: 8 | B17: igp-november | C17: Pakistan | D17: 54.3 | E17: 57.7 | F17: 53.5 | G17: 57.9 | H17: 58.4 | I17: 57.9–59 | J17: =IFERROR(H17/D17-1,"") | K17: =H17/WHO_PM25_ANNUAL | L17: 46 | M17: 64.1 | N17: 247900 | O17: 206,700–286,700 | P17: 99100 | Q17: 143500 | R17: 177 | S17: p.4, 24: >200,000 deaths
A18: 9 | B18: harmattan | C18: Niger | D18: 57.1 | E18: 82.6 | F18: 55.5 | G18: 74.6 | H18: 65.2 | I18: 64.6–65.8 | J18: =IFERROR(H18/D18-1,"") | K18: =H18/WHO_PM25_ANNUAL | L18: 97.4 | M18: 48.6 | N18: 33500 | O18: 25,200–41,700 | P18: 5720 | Q18: 27500 | R18: 230 | T18: Niger's yearly PM2.5 was 65 µg/m³ in 2023, 13 times the WHO annual guideline, much of it Saharan dust. 97% of people there also cook with solid fuels.
A19: 9 | B19: harmattan | C19: Nigeria | D19: 52.2 | E19: 75.1 | F19: 56.2 | G19: 70.6 | H19: 65.7 | I19: 65.2–66.4 | J19: =IFERROR(H19/D19-1,"") | K19: =H19/WHO_PM25_ANNUAL | L19: 66.6 | M19: 53.6 | N19: 205800 | O19: 161,900–243,200 | P19: 81600 | Q19: 123000 | R19: 151 | S19: p.4, 24: >200,000 deaths
A20: 9 | B20: harmattan | C20: Chad | D20: 42.9 | E20: 53 | F20: 41.6 | G20: 42.4 | H20: 43 | I20: 42.6–43.4 | J20: =IFERROR(H20/D20-1,"") | K20: =H20/WHO_PM25_ANNUAL | L20: 95.4 | M20: 47.8 | N20: 23900 | O20: 19,100–28,500 | P20: 3990 | Q20: 20200 | R20: 246
A21: 10 | B21: sahel-burning | C21: Central African Republic | D21: 38.2 | E21: 37.4 | F21: 34 | G21: 32.6 | H21: 33.3 | I21: 32.6–34.1 | J21: =IFERROR(H21/D21-1,"") | K21: =H21/WHO_PM25_ANNUAL | L21: 99.3 | M21: 54.2 | N21: 9220 | O21: 6,990–11,200 | P21: 941 | Q21: 8190 | R21: 249 | S21: p.16: >99% exposed to household smoke | T21: In the Central African Republic, 99% of people cook with wood, charcoal or other solid fuels (2023), among the highest shares in the world.
A22: 10 | B22: sahel-burning | C22: Cameroon | D22: 52.8 | E22: 61.7 | F22: 52.9 | G22: 56.6 | H22: 55.6 | I22: 54.3–56.9 | J22: =IFERROR(H22/D22-1,"") | K22: =H22/WHO_PM25_ANNUAL | L22: 71.5 | M22: 51.1 | N22: 28100 | O22: 21,900–34,100 | P22: 7770 | Q22: 20500 | R22: 185
A23: 10 | B23: sahel-burning | C23: Nigeria | D23: 52.2 | E23: 75.1 | F23: 56.2 | G23: 70.6 | H23: 65.7 | I23: 65.2–66.4 | J23: =IFERROR(H23/D23-1,"") | K23: =H23/WHO_PM25_ANNUAL | L23: 66.6 | M23: 53.6 | N23: 205800 | O23: 161,900–243,200 | P23: 81600 | Q23: 123000 | R23: 151 | S23: p.4, 24: >200,000 deaths
A24: 11 | B24: saharan-dust-caribbean | C24: Puerto Rico | D24: 6.54 | E24: 6.69 | F24: 7.82 | G24: 6.34 | H24: 7.84 | I24: 7.03–8.79 | J24: =IFERROR(H24/D24-1,"") | K24: =H24/WHO_PM25_ANNUAL | L24: 0.06 | M24: 24.6 | N24: 915 | O24: 455–1560 | P24: 908 | Q24: 2.18 | R24: 9.66 | T24: Puerto Rico's yearly PM2.5 was 7.8 µg/m³ in 2023 and Cuba's 9.5, among the lowest of the countries in this deck.
A25: 11 | B25: saharan-dust-caribbean | C25: Cuba | D25: 9.42 | E25: 9.35 | F25: 9.26 | G25: 9.41 | H25: 9.45 | I25: 9.18–9.66 | J25: =IFERROR(H25/D25-1,"") | K25: =H25/WHO_PM25_ANNUAL | L25: 1.17 | M25: 34.2 | N25: 5120 | O25: 3,260–7,370 | P25: 4690 | Q25: 262 | R25: 24.3
A26: 11 | B26: saharan-dust-caribbean | C26: Dominican Republic | D26: 12.1 | E26: 13 | F26: 13.3 | G26: 12.8 | H26: 13.5 | I26: 13.1–13.9 | J26: =IFERROR(H26/D26-1,"") | K26: =H26/WHO_PM25_ANNUAL | L26: 6.53 | M26: 33.6 | N26: 5190 | O26: 3,700–6,840 | P26: 4520 | Q26: 635 | R26: 54.9
A27: 12 | B27: central-africa-burning | C27: Democratic Republic of the Congo | D27: 41.4 | E27: 40.5 | F27: 37.4 | G27: 36.8 | H27: 35.8 | I27: 35.5–36.1 | J27: =IFERROR(H27/D27-1,"") | K27: =H27/WHO_PM25_ANNUAL | L27: 91.1 | M27: 48.3 | N27: 89600 | O27: 67,300–106,800 | P27: 11400 | Q27: 77100 | R27: 211 | T27: In DR Congo, 91% of people cook with solid fuels. Of about 90,000 deaths linked to air pollution there in 2023, 77,000 were from household smoke.
A28: 12 | B28: central-africa-burning | C28: Angola | D28: 22.6 | E28: 21.2 | F28: 22.2 | G28: 22.5 | H28: 19.9 | I28: 19.2–20.6 | J28: =IFERROR(H28/D28-1,"") | K28: =H28/WHO_PM25_ANNUAL | L28: 28.6 | M28: 42.5 | N28: 18300 | O28: 14,100–22,300 | P28: 6730 | Q28: 11300 | R28: 108
A29: 12 | B29: central-africa-burning | C29: Zambia | D29: 22.1 | E29: 22.8 | F29: 22.1 | G29: 23.5 | H29: 20.2 | I29: 20–20.6 | J29: =IFERROR(H29/D29-1,"") | K29: =H29/WHO_PM25_ANNUAL | L29: 84.9 | M29: 43.7 | N29: 13800 | O29: 10,600–16,800 | P29: 2000 | Q29: 11700 | R29: 172
A30: 13 | B30: mainland-sea-burning | C30: Myanmar | D30: 36.1 | E30: 34.6 | F30: 36.7 | G30: 32.8 | H30: 35.1 | I30: 34.8–35.4 | J30: =IFERROR(H30/D30-1,"") | K30: =H30/WHO_PM25_ANNUAL | L30: 75.3 | M30: 42.6 | N30: 125900 | O30: 103,800–149,300 | P30: 36500 | Q30: 88000 | R30: 286 | S30: p.4, 24: >100,000 deaths | T30: Death rates linked to air pollution in Myanmar (286 per 100,000) and Laos (272) are about three times the world rate of 92 (2023). Most of it is household cooking smoke.
A31: 13 | B31: mainland-sea-burning | C31: Lao People's Democratic Republic | D31: 28.5 | E31: 26.3 | F31: 27.9 | G31: 25.3 | H31: 26 | I31: 25.6–26.4 | J31: =IFERROR(H31/D31-1,"") | K31: =H31/WHO_PM25_ANNUAL | L31: 97 | M31: 42.3 | N31: 12800 | O31: 10,000–15,100 | P31: 3060 | Q31: 9690 | R31: 272
A32: 13 | B32: mainland-sea-burning | C32: Thailand | D32: 27.2 | E32: 23.6 | F32: 24 | G32: 23.7 | H32: 23.5 | I32: 22.9–24.1 | J32: =IFERROR(H32/D32-1,"") | K32: =H32/WHO_PM25_ANNUAL | L32: 12.4 | M32: 46.3 | N32: 54700 | O32: 40,600–73,500 | P32: 50900 | Q32: 2160 | R32: 48
A33: 14 | B33: mexico-burning | C33: Mexico | D33: 17.6 | E33: 17 | F33: 17.1 | G33: 16.6 | H33: 16.6 | I33: 16.1–17.1 | J33: =IFERROR(H33/D33-1,"") | K33: =H33/WHO_PM25_ANNUAL | L33: 10.5 | M33: 42.8 | N33: 61400 | O33: 46,700–76,800 | P33: 54100 | Q33: 5580 | R33: 47.9 | T33: In Guatemala, 47% of people cook with solid fuels; in Mexico, 10.5% (2023).
A34: 14 | B34: mexico-burning | C34: Guatemala | D34: 32 | E34: 26.9 | F34: 29.4 | G34: 28.3 | H34: 29.7 | I34: 26.5–32.8 | J34: =IFERROR(H34/D34-1,"") | K34: =H34/WHO_PM25_ANNUAL | L34: 46.8 | M34: 35.1 | N34: 10600 | O34: 8,060–13,000 | P34: 4520 | Q34: 6020 | R34: 108
A35: 15 | B35: gobi-dust | C35: China | D35: 51.7 | E35: 49.5 | F35: 37.2 | G35: 31.9 | H35: 32 | I35: 31.8–32.1 | J35: =IFERROR(H35/D35-1,"") | K35: =H35/WHO_PM25_ANNUAL | L35: 32.3 | M35: 48.4 | N35: 2051000 | O35: 1,577,000–2,525,000 | P35: 1790000 | Q35: 216800 | R35: 95.3 | S35: p.4, 24: >2 million deaths | T35: China's yearly PM2.5 fell from 52 µg/m³ in 2013 to 32 in 2023. Air pollution was still linked to about 2 million deaths there in 2023.
A36: 15 | B36: gobi-dust | C36: Mongolia | D36: 45.4 | E36: 44.9 | F36: 44.2 | G36: 40.9 | H36: 42.7 | I36: 38.3–46.7 | J36: =IFERROR(H36/D36-1,"") | K36: =H36/WHO_PM25_ANNUAL | L36: 40.3 | M36: 42.9 | N36: 2460 | O36: 1,930–3,010 | P36: 1910 | Q36: 544 | R36: 125
A37: 15 | B37: gobi-dust | C37: Republic of Korea | D37: 25.1 | E37: 24.5 | F37: 22 | G37: 23.4 | H37: 21.9 | I37: 21.2–22.5 | J37: =IFERROR(H37/D37-1,"") | K37: =H37/WHO_PM25_ANNUAL | L37: 0.24 | M37: 59.3 | N37: 36800 | O37: 26,000–53,000 | P37: 34800 | Q37: 81.1 | R37: 37.3
A38: 16 | B38: canada-nwt-2023 | C38: Canada | D38: 7.14 | E38: 7.39 | F38: 6.45 | G38: 6.39 | H38: 6.55 | I38: 6.34–6.77 | J38: =IFERROR(H38/D38-1,"") | K38: =H38/WHO_PM25_ANNUAL | L38: 0.16 | M38: 37.2 | N38: 7060 | O38: 3,740–12,200 | P38: 6270 | Q38: 29.3 | R38: 8.23 | T38: Same country figures as canada-2023.
A39: 17 | B39: indonesia-2023 | C39: Indonesia | D39: 19.4 | E39: 25.6 | F39: 24 | G39: 19.8 | H39: 20.8 | I39: 20.2–21.5 | J39: =IFERROR(H39/D39-1,"") | K39: =H39/WHO_PM25_ANNUAL | L39: 18 | M39: 38 | N39: 192100 | O39: 146,200–242,500 | P39: 147100 | Q39: 42700 | R39: 82.2 | S39: p.4, 24: >100,000 deaths | T39: Indonesia's yearly PM2.5 was 20.8 µg/m³ in 2023, below the haze years 2015 (25.6) and 2019 (24.0).
A40: 18 | B40: gulf-shamal | C40: Saudi Arabia | D40: 73 | E40: 76.8 | F40: 71.1 | G40: 77.8 | H40: 73.5 | I40: 72–75 | J40: =IFERROR(H40/D40-1,"") | K40: =H40/WHO_PM25_ANNUAL | L40: 0.25 | M40: 58.5 | N40: 14800 | O40: 11,700–17,400 | P40: 14600 | Q40: 9.88 | R40: 152 | S40: p.9: PM2.5 74 µg/m³ | T40: Saudi Arabia's yearly PM2.5 (74 µg/m³) is the second highest in the world after Qatar (108); the report puts much of it down to windblown dust.
...

Sheet SoGA checks
A1: Report figure | B1: Page | C1: Report says | D1: Site data | E1: Result
A2: Qatar yearly PM2.5, 2023 | B2: 9 | C2: 108 ug/m3 | D2: 108 | E2: Matches
A3: Saudi Arabia yearly PM2.5, 2023 | B3: 9 | C3: 74 ug/m3 | D3: 73.5 | E3: Matches
A4: Bangladesh yearly PM2.5, 2023 | B4: 9 | C4: 69 ug/m3 | D4: 69.3 | E4: Matches
A5: Qatar ozone, 2020 | B5: 12 | C5: 67.6 ppb | D5: 67.6 | E5: Matches
A6: India ozone, 2020 | B6: 12 | C6: 67.2 ppb | D6: 67.2 | E6: Matches
A7: Bangladesh ozone, 2020 | B7: 12 | C7: 65.4 ppb | D7: 65.4 | E7: Matches
A8: India deaths, 2023 | B8: 4 | C8: > 2 million | D8: 2006000 | E8: Matches
A9: China deaths, 2023 | B9: 4 | C9: > 2 million | D9: 2051000 | E9: Matches
A10: Bangladesh deaths, 2023 | B10: 4 | C10: > 200,000 | D10: 271300 | E10: Matches
A11: Pakistan deaths, 2023 | B11: 4 | C11: > 200,000 | D11: 247900 | E11: Matches
A12: Nigeria deaths, 2023 | B12: 4 | C12: > 200,000 | D12: 205800 | E12: Matches
A13: Indonesia deaths, 2023 | B13: 4 | C13: > 100,000 | D13: 192100 | E13: Matches
... A16: Central African Republic, cooking with solid fuels | B16: 16 | C16: > 99% | D16: 99.3 | E16: Matches
A17: Singapore NO2, 2023 | B17: 13 | C17: 22 ppb | D17: 41.3 ug/m3 | E17: Matches after unit conversion (22 ppb x 1.88 = 41.4 ug/m3). The report prints ppb; the site gives ug/m3.
A19: Errors in the report text (do not quote these lines)
A20: WHO roadmap target year | B20: 6 | C20: "by 2024" | E20: Pages 27 and 34 say 2040. 2040 is right.
A21: Share of PM2.5 deaths from noncommunicable diseases | B21: 29 | C21: "4.5 million, or 67%" | E21: 4.5 of 4.9 million is 92%.
A22: Dementia deaths from PM2.5, uncertainty range | B22: 29 | C22: "60,000–1.5" | E22: Missing "million".
A23: China clean-air paragraph | B23: 30 | C23: "Chinese cities (YEAR)" | E23: Unfilled placeholder.
A24: NO2 interim targets | B24: 14 | C24: "two interim targets ... 40, 30, and 20" | E24: Three targets are listed.
A25: Executive summary | B25: 4 | C25: "86% of global deaths were attributable to air pollution" | E25: Means: 86% of air-pollution deaths were from noncommunicable diseases.
A26: Deaths by pollutant | B26: 22 | C26: 4.9 + 2.8 + 0.47 million | E26: Adds to 8.17 million against a 7.9 million total (Figure 12 adds to 102.9%). Overlap between pollutants, not explained in the report.
A27: Ozone countries meeting IT-1 | B27: 11 | C27: "In 2023 ... 164 countries" | E27: Ozone exposure data stops at 2020 in this edition.
